<?xml version="1.0" encoding="UTF-8"?>
<sdf version="1.4">
   <model name="RA605">
      <static>false</static>
      <link name="base">
         <pose>0.000000 0.000000 0.12 0.000000 0.000000 0.000000</pose>
         <inertial>
            <mass>100</mass>
            <inertia>
               <ixx>0.1</ixx>
               <ixy>0.0</ixy>
               <iyy>0.1</iyy>
               <ixz>0.0</ixz>
               <iyz>0.0</iyz>
               <izz>0.1</izz>
            </inertia>
         </inertial>
         <collision name="base">
            <geometry>
               <mesh>
                  <scale>0.1 0.1 0.1</scale>
                  <uri>/home/kevin/research/gazebo/Arm_Control3_RA605/model/RA605/mesh/base.dae</uri>
               </mesh>
            </geometry>
            <surface>
               <friction>
                  <ode>
                     <mu>100</mu>
                     <mu2>50</mu2>
                  </ode>
                              </friction>
					<contact>
				           <collide_without_contact>true    </collide_without_contact>
					</contact>
            </surface>
         </collision>
         <visual name="base">
            <geometry>
               <mesh>
                  <scale>0.1 0.1 0.1</scale>
                  <uri>/home/kevin/research/gazebo/Arm_Control3_RA605/model/RA605/mesh/base.dae</uri>
               </mesh>
            </geometry>
         </visual>
      </link>
      <link name="link1">
         <pose>0.000000 0.000000 0.26 0.000000 0.000000 0.000000</pose>
         <inertial>
            <mass>0.1</mass>
            <inertia>
               <ixx>0.1</ixx>
               <ixy>0.0</ixy>
               <iyy>0.1</iyy>
               <ixz>0.0</ixz>
               <iyz>0.0</iyz>
               <izz>0.1</izz>
            </inertia>
         </inertial>
         <collision name="link1">
            <geometry>
               <mesh>
                  <scale>0.1 0.1 0.1</scale>
                  <uri>/home/kevin/research/gazebo/Arm_Control3_RA605/model/RA605/mesh/link1.dae</uri>
               </mesh>
            </geometry>
            <surface>
               <friction>
                  <ode>
                     <mu>100</mu>
                     <mu2>50</mu2>
                  </ode>
                              </friction>
					<contact>
				           <collide_without_contact>true    </collide_without_contact>
					</contact>
            </surface>
         </collision>
         <visual name="link1">
            <geometry>
               <mesh>
                  <scale>0.1 0.1 0.1</scale>
                  <uri>/home/kevin/research/gazebo/Arm_Control3_RA605/model/RA605/mesh/link1.dae</uri>
               </mesh>
            </geometry>
         </visual>
      </link>
      <link name="link2">
         <pose>0.0000 0.000 0.41 0.000000 0.000000 0.000000</pose>
         <inertial>
            <mass>0.1</mass>
            <inertia>
               <ixx>0.1</ixx>
               <ixy>0.0</ixy>
               <iyy>0.1</iyy>
               <ixz>0.0</ixz>
               <iyz>0.0</iyz>
               <izz>0.1</izz>
            </inertia>
         </inertial>
         <collision name="link2">
            <geometry>
               <mesh>
                  <scale>0.1 0.1 0.1</scale>
                  <uri>/home/kevin/research/gazebo/Arm_Control3_RA605/model/RA605/mesh/link2.dae</uri>
               </mesh>
            </geometry>
            <surface>
               <friction>
                  <ode>
                     <mu>100</mu>
                     <mu2>50</mu2>
                  </ode>
                              </friction>
					<contact>
				           <collide_without_contact>true    </collide_without_contact>
					</contact>
            </surface>
         </collision>
         <visual name="link2">
            <geometry>
               <mesh>
                  <scale>0.1 0.1 0.1</scale>
                  <uri>/home/kevin/research/gazebo/Arm_Control3_RA605/model/RA605/mesh/link2.dae</uri>
               </mesh>
            </geometry>
         </visual>
      </link>
      <link name="link3">
         <pose>0.0000 0.000 0.73 0.000000 0.000000 0.000000</pose>
         <inertial>
            <mass>0.1</mass>
            <inertia>
               <ixx>0.1</ixx>
               <ixy>0.0</ixy>
               <iyy>0.1</iyy>
               <ixz>0.0</ixz>
               <iyz>0.0</iyz>
               <izz>0.1</izz>
            </inertia>
         </inertial>
         <collision name="link3">
            <geometry>
               <mesh>
                  <scale>0.1 0.1 0.1</scale>
                  <uri>/home/kevin/research/gazebo/Arm_Control3_RA605/model/RA605/mesh/link3.dae</uri>
               </mesh>
            </geometry>
            <surface>
               <friction>
                  <ode>
                     <mu>100</mu>
                     <mu2>50</mu2>
                  </ode>
                              </friction>
					<contact>
				           <collide_without_contact>true    </collide_without_contact>
					</contact>
            </surface>
         </collision>
         <visual name="link3">
            <geometry>
               <mesh>
                  <scale>0.1 0.1 0.1</scale>
                  <uri>/home/kevin/research/gazebo/Arm_Control3_RA605/model/RA605/mesh/link3.dae</uri>
               </mesh>
            </geometry>
         </visual>
      </link>
      <link name="link4">
         <pose>0.0 0.00 0.75 0.000000 0.000000 0.000000</pose>
         <inertial>
            <mass>0.1</mass>
            <inertia>
               <ixx>0.1</ixx>
               <ixy>0.0</ixy>
               <iyy>0.1</iyy>
               <ixz>0.0</ixz>
               <iyz>0.0</iyz>
               <izz>0.1</izz>
            </inertia>
         </inertial>
         <collision name="link4">
            <geometry>
               <mesh>
                  <scale>0.1 0.1 0.1</scale>
                  <uri>/home/kevin/research/gazebo/Arm_Control3_RA605/model/RA605/mesh/link4.dae</uri>
               </mesh>
            </geometry>
            <surface>
               <friction>
                  <ode>
                     <mu>100</mu>
                     <mu2>50</mu2>
                  </ode>
                              </friction>
					<contact>
				           <collide_without_contact>true    </collide_without_contact>
					</contact>
            </surface>
         </collision>
         <visual name="link4">
            <geometry>
               <mesh>
                  <scale>0.1 0.1 0.1</scale>
                  <uri>/home/kevin/research/gazebo/Arm_Control3_RA605/model/RA605/mesh/link4.dae</uri>
               </mesh>
            </geometry>
         </visual>
      </link>
      <link name="link5">
         <pose>0.43 0.0 0.76 0.000000 0.000000 0.000000</pose>
         <inertial>
            <mass>0.1</mass>
            <inertia>
               <ixx>0.1</ixx>
               <ixy>0.0</ixy>
               <iyy>0.1</iyy>
               <ixz>0.0</ixz>
               <iyz>0.0</iyz>
               <izz>0.1</izz>
            </inertia>
         </inertial>
         <collision name="link5">
            <geometry>
               <mesh>
                  <scale>0.1 0.1 0.1</scale>
                  <uri>/home/kevin/research/gazebo/Arm_Control3_RA605/model/RA605/mesh/link5.dae</uri>
               </mesh>
            </geometry>
            <surface>
               <friction>
                  <ode>
                     <mu>100</mu>
                     <mu2>50</mu2>
                  </ode>
                              </friction>
					<contact>
				           <collide_without_contact>true    </collide_without_contact>
					</contact>
            </surface>
         </collision>
         <visual name="link5">
            <geometry>
               <mesh>
                  <scale>0.1 0.1 0.1</scale>
                  <uri>/home/kevin/research/gazebo/Arm_Control3_RA605/model/RA605/mesh/link5.dae</uri>
               </mesh>
            </geometry>
         </visual>
      </link>
      <link name="link6">
         <pose>0.43 0 0.76.000000 0.000000 0.000000</pose>
         <inertial>
            <mass>0.1</mass>
            <inertia>
               <ixx>0.1</ixx>
               <ixy>0.0</ixy>
               <iyy>0.1</iyy>
               <ixz>0.0</ixz>
               <iyz>0.0</iyz>
               <izz>0.1</izz>
            </inertia>
         </inertial>
         <collision name="link6">
            <geometry>
               <mesh>
                  <scale>0.1 0.1 0.1</scale>
                  <uri>/home/kevin/research/gazebo/Arm_Control3_RA605/model/RA605/mesh/link6.dae</uri>
               </mesh>
            </geometry>
            <surface>
               <friction>
                  <ode>
                     <mu>100</mu>
                     <mu2>50</mu2>
                  </ode>
                              </friction>
					<contact>
				           <collide_without_contact>true    </collide_without_contact>
					</contact>
            </surface>
         </collision>
         <visual name="link6">
            <geometry>
               <mesh>
                  <scale>0.1 0.1 0.1</scale>
                  <uri>/home/kevin/research/gazebo/Arm_Control3_RA605/model/RA605/mesh/link6.dae</uri>
               </mesh>
            </geometry>
         </visual>
      </link>
      <!-- -- -- -- -- -- -- -- -- -- -- -- -- -- -- -- -- -- -- -- -- -- -- -- -- -- -- -- -- -- -- -- -- -- -->
      <joint name="joint0" type="revolute">
         <pose>0.000000 0.000000 0.0 0.000000 0.000000 0.000000</pose>
         <child>base</child>
         <parent>world</parent>
         <axis>
            <xyz>0 0 1</xyz>
            <limit>
               <lower>-0.001</lower>
               <upper>0.001</upper>
            </limit>
         </axis>
      </joint>
      <joint name="joint1" type="revolute">
         <pose>0.000000 0.000000 0.0 0.000000 0.000000 0.000000</pose>
         <child>link1</child>
         <parent>base</parent>
         <axis>
            <xyz>0 0 1</xyz>
            <limit>
               <lower>-1.4835</lower>
               <upper>2.2689</upper>
            </limit>
         </axis>
      </joint>
      
      <joint name="joint2" type="revolute">
         <pose>0.000000 0.000000 0.0 0.000000 0.000000 0.000000</pose>
         <child>link2</child>
         <parent>link1</parent>
         <axis>
            <xyz>0 1 0</xyz>
            <limit>
               <lower>-1.919</lower>
               <upper>2.967</upper>
            </limit>
         </axis>
      </joint>
     
      <joint name="joint3" type="revolute">
         <pose>0.000000 0.000000 0.0 0.000000 0.000000 0.000000</pose>
         <child>link3</child>
         <parent>link2</parent>
         <axis>
            <xyz>0 1 0</xyz>
            <limit>
               <lower>-3.316</lower>
               <upper>3.316</upper>
            </limit>
         </axis>
      </joint>
      <joint name="joint4" type="revolute">
         <pose>0.000000 0.000000 0.0 0.000000 0.000000 0.000000</pose>
         <child>link4</child>
         <parent>link3</parent>
         <axis>
            <xyz>1 0 0</xyz>
            <limit>
               <lower>-2.1816</lower>
               <upper>2.1816</upper>
            </limit>
         </axis>
      </joint>
       <joint name="joint5" type="revolute">
         <pose>0.000000 0.000000 0.0 0.000000 0.000000 0.000000</pose>
         <child>link5</child>
         <parent>link4</parent>
         <axis>
            <xyz>0 1 0</xyz>
            <limit>
               <lower>-6.28</lower>
               <upper>6.28</upper>
            </limit>
         </axis>
      </joint>
      <joint name="joint6" type="revolute">
         <pose>0.000000 0.000000 0.0 0.000000 0.000000 0.000000</pose>
         <child>link6</child>
         <parent>link5</parent>
         <axis>
            <xyz>1 0 0</xyz>
            <limit>
               <lower>-6.28</lower>
               <upper>6.28</upper>
            </limit>
         </axis>
      </joint> <!---->
      <plugin name='ff' filename='/home/kevin/research/gazebo/Arm_Control3_RA605/Debug/libArm_Control3_RA605.so'/>
   </model>
</sdf>
