<?xml version="1.0" ?>
<sdf version="1.4">
  <model name="2link_model_kinematics">
    

 <link name="Base">
	<!--<self_collide> true <self_collide>-->
		<pose>0 0 -0.01 0 0 0</pose>
			<inertial>
				<mass> 400 </mass>
			</inertial> 
			<collision name="Base_collision">
        <geometry>
          <box>
            <size>0.5 0.5 0.01</size>
          </box>
        </geometry>

      </collision>
      <visual name="Base_visual">
        <geometry>
          <box>
            <size>0.5 0.5 0.01</size>
          </box>
        </geometry>
      </visual>
    </link>


<!--joint_base_1-->


		<joint name="base_to_link1" type="revolute">
			     
			<pose>0 0.01 -0.495 0 0 0</pose>
      <child>Link1</child>
      <parent>Base</parent>
      <axis>
      	<xyz> 1 0 0</xyz>
     	</axis>
    </joint>

<!--link1-->




    <link name="Link1">
		<!--<self_collide> true <self_collide>-->

		<pose>0 0.5 0.01 -1.5708 0 0</pose>
			<inertial>
				<mass> 20 </mass>
			</inertial> 
			<collision name="collision1">
        <geometry>
          <box>
            <size>0.02 0.02 1</size>
          </box>
        </geometry>

      </collision>
      <visual name="visual1">
        <geometry>
          <box>
            <size>0.02 0.02 1</size>
          </box>
        </geometry>
      </visual>
    </link>

<!--joint_1_2-->


		<joint name="link1_to_link2" type="revolute">
			     
			<pose>0 0.01 0.2 0 0 0</pose>
      <child>Link2</child>
      <parent>Link1</parent>
      <axis>
      	<xyz> 1 0 0</xyz>
     	</axis>
    </joint>

<!--link2-->
	
    <link name="Link2">
		<!--<self_collide> true <self_collide>-->
		<pose>0 1.2 0.01 1.5708 0 0</pose>
			<inertial>
				<mass> 0.2 </mass>
			</inertial> 
			<collision name="collision2">
        <geometry>
          <box>
            <size>0.02 0.02 0.4</size>
          </box>
        </geometry>
      </collision>
      <visual name="visual2">
        <geometry>
          <box>
            <size>0.02 0.02 0.4</size>
          </box>
        </geometry>
      </visual>
    </link>
<!--FingerTip
	    <link name="FingerTip">
		
		<pose>0 0 1.39 0 0 0</pose>
			<inertial>
				<mass> 0.1 </mass>
			</inertial> 
			<collision name="FingerTip_collision">
        <geometry>
          <sphere>
            <radius>.015</radius>
          </sphere>
        </geometry>
      </collision>
      <visual name="FingerTip_visual">
        <geometry>
          <sphere>
						<radius>.015</radius>
					</sphere>
        </geometry>
      </visual>
    </link>
-->






<plugin name="libmodel_kinematics" filename="/home/gotony5614/NetBeansProjects/model_kinematic/dist/Debug/GNU-Linux-x86/libmodel_kinematic.so"/>

  </model>    
</sdf>
