<?xml version="1.0" encoding="UTF-8"?>
<sdf version="1.4">
   <model name="axis7">
	<static>false</static>
      <link name="base">
         <pose>0.000000 0.000000 -1.0 0.000000 0.000000 0.000000</pose>
         <inertial>
            <mass>100</mass>
            <inertia>
               <ixx>0.1</ixx>
               <ixy>0.0</ixy>
               <iyy>0.1</iyy>
               <ixz>0.0</ixz>
               <iyz>0.0</iyz>
               <izz>0.1</izz>
            </inertia>
         </inertial>
         <collision name="base">
            <geometry>
               <mesh>
                  <uri>/home/kevin/research/gazebo/Arm_Control3_7axis/model/axis7/mesh/link1.dae</uri>
               </mesh>
            </geometry>
            <surface>
               <friction>
                  <ode>
                     <mu>100</mu>
                     <mu2>50</mu2>
                  </ode>
               </friction>
            </surface>
         </collision>
         <visual name="base">
            <geometry>
               <mesh>
                  <uri>/home/kevin/research/gazebo/Arm_Control3_7axis/model/axis7/mesh/link1.dae</uri>
               </mesh>
            </geometry>
         </visual>
      </link>
    <link name="link1">
         <pose>0.000000 0.000000 1.145 0.000000 0.000000 0.000000</pose>
         <inertial>
            <mass>0.1</mass>
            <inertia>
               <ixx>0.1</ixx>
               <ixy>0.0</ixy>
               <iyy>0.1</iyy>
               <ixz>0.0</ixz>
               <iyz>0.0</iyz>
               <izz>0.1</izz>
            </inertia>
         </inertial>
         <collision name="link1">
            <geometry>
               <mesh>
                  <uri>/home/kevin/research/gazeboy/Arm_Control3_7axis/model/axis7/mesh/link2.dae</uri>
               </mesh>
            </geometry>
            <surface>
               <friction>
                  <ode>
                     <mu>100</mu>
                     <mu2>50</mu2>
                  </ode>
               </friction>
            </surface>
         </collision>
         <visual name="link1">
            <geometry>
               <mesh>
                  <uri>/home/kevin/research/gazebo/Arm_Control3_7axis/model/axis7/mesh/link2.dae</uri>
               </mesh>
            </geometry>
         </visual>
      </link>
    <link name="link2">
         <pose>0.0000 0.000 1.145 0.000000 0.000000 0.000000</pose>
         <inertial>
            <mass>0.1</mass>
            <inertia>
               <ixx>0.1</ixx>
               <ixy>0.0</ixy>
               <iyy>0.1</iyy>
               <ixz>0.0</ixz>
               <iyz>0.0</iyz>
               <izz>0.1</izz>
            </inertia>
         </inertial>
         <collision name="link2">
            <geometry>
               <mesh>
                  <uri>/home/kevin/research/gazebo/Arm_Control3_7axis/model/axis7/mesh/link3.dae</uri>
               </mesh>
            </geometry>
            <surface>
               <friction>
                  <ode>
                     <mu>100</mu>
                     <mu2>50</mu2>
                  </ode>
               </friction>
            </surface>
         </collision>
         <visual name="link2">
            <geometry>
               <mesh>
                  <uri>/home/kevin/research/gazebo/Arm_Control3_7axis/model/axis7/mesh/link3.dae</uri>
               </mesh>
            </geometry>
         </visual>
      </link>
       <link name="link3">
         <pose>0.0000 0.000 3.430 0.000000 0.000000 0.000000</pose>
         <inertial>
            <mass>0.1</mass>
            <inertia>
               <ixx>0.1</ixx>
               <ixy>0.0</ixy>
               <iyy>0.1</iyy>
               <ixz>0.0</ixz>
               <iyz>0.0</iyz>
               <izz>0.1</izz>
            </inertia>
         </inertial>
         <collision name="link3">
            <geometry>
               <mesh>
                  <uri>/home/kevin/research/gazebo/Arm_Control3_7axis/model/axis7/mesh/link4.dae</uri>
               </mesh>
            </geometry>
            <surface>
               <friction>
                  <ode>
                     <mu>100</mu>
                     <mu2>50</mu2>
                  </ode>
               </friction>
            </surface>
         </collision>
         <visual name="link3">
            <geometry>
               <mesh>
                  <uri>/home/kevin/research/gazebo/Arm_Control3_7axis/model/axis7/mesh/link4.dae</uri>
               </mesh>
            </geometry>
         </visual>
      </link>
      <link name="link4">
         <pose>0.0 0.00 3.43 0.000000 0.000000 0.000000</pose>
         <inertial>
            <mass>0.1</mass>
            <inertia>
               <ixx>0.1</ixx>
               <ixy>0.0</ixy>
               <iyy>0.1</iyy>
               <ixz>0.0</ixz>
               <iyz>0.0</iyz>
               <izz>0.1</izz>
            </inertia>
         </inertial>
         <collision name="link4">
            <geometry>
               <mesh>
                  <uri>/home/kevin/research/gazebo/Arm_Control3_7axis/model/axis7/mesh/link5.dae</uri>
               </mesh>
            </geometry>
            <surface>
               <friction>
                  <ode>
                     <mu>100</mu>
                     <mu2>50</mu2>
                  </ode>
               </friction>
            </surface>
         </collision>
         <visual name="link4">
            <geometry>
               <mesh>
                  <uri>/home/kevin/research/gazebo/Arm_Control3_7axis/model/axis7/mesh/link5.dae</uri>
               </mesh>
            </geometry>
         </visual>
      </link>
       <link name="link5">
         <pose>-1.445 0.0 3.43 0.000000 0.000000 0.000000</pose>
         <inertial>
            <mass>0.1</mass>
            <inertia>
               <ixx>0.1</ixx>
               <ixy>0.0</ixy>
               <iyy>0.1</iyy>
               <ixz>0.0</ixz>
               <iyz>0.0</iyz>
               <izz>0.1</izz>
            </inertia>
         </inertial>
         <collision name="link5">
            <geometry>
               <mesh>
                  <uri>/home/kevin/research/gazebo/Arm_Control3_7axis/model/axis7/mesh/link6.dae</uri>
               </mesh>
            </geometry>
            <surface>
               <friction>
                  <ode>
                     <mu>100</mu>
                     <mu2>50</mu2>
                  </ode>
               </friction>
            </surface>
         </collision>
         <visual name="link5">
            <geometry>
               <mesh>
                  <uri>/home/kevin/research/gazebo/Arm_Control3_7axis/model/axis7/mesh/link6.dae</uri>
               </mesh>
            </geometry>
         </visual>
      </link>
 <link name="link6">
         <pose>-1.425 0 5.275.000000 0.000000 0.000000</pose>
         <inertial>
            <mass>0.1</mass>
            <inertia>
               <ixx>0.1</ixx>
               <ixy>0.0</ixy>
               <iyy>0.1</iyy>
               <ixz>0.0</ixz>
               <iyz>0.0</iyz>
               <izz>0.1</izz>
            </inertia>
         </inertial>
         <collision name="link6">
            <geometry>
               <mesh>
                  <uri>/home/kevin/research/gazebo/Arm_Control3_7axis/model/axis7/mesh/link7.dae</uri>
               </mesh>
            </geometry>
            <surface>
               <friction>
                  <ode>
                     <mu>100</mu>
                     <mu2>50</mu2>
                  </ode>
               </friction>
            </surface>
         </collision>
         <visual name="link6">
            <geometry>
               <mesh>
                  <uri>/home/kevin/research/gazebo/Arm_Control3_7axis/model/axis7/mesh/link7.dae</uri>
               </mesh>
            </geometry>
         </visual>
      </link>      <!-- -->
	

      <joint name="joint1" type="revolute">
         <pose>0.000000 0.000000 0.0 0.000000 0.000000 0.000000</pose>
         <child>link1</child>
         <parent>base</parent>
         <axis>
            <xyz>0 0 1 </xyz>
            <limit>
               <lower>-1.4835</lower>
               <upper>2.2689</upper>
            </limit>
         </axis>
      </joint>
      <joint name="joint2" type="revolute">
         <pose>0.000000 0.000000 0.0 0.000000 0.000000 0.000000</pose>
         <child>link2</child>
         <parent>link1</parent>
         <axis>
            <xyz>1 0 0</xyz>
            <limit>
               <lower>-1.919</lower>
               <upper>2.967</upper>
            </limit>
         </axis>
      </joint>
      <joint name="joint3" type="revolute">
         <pose>0.000000 0.000000 0.0 0.000000 0.000000 0.000000</pose>
         <child>link3</child>
         <parent>link2</parent>
         <axis>
            <xyz>0 0 1</xyz>
            <limit>
               <lower>-3.316</lower>
               <upper>3.316</upper>
            </limit>
         </axis>
      </joint>
      <joint name="joint4" type="revolute">
         <pose>0.000000 0.000000 0.0 0.000000 0.000000 0.000000</pose>
         <child>link4</child>
         <parent>link3</parent>
         <axis>
            <xyz>1 0 0</xyz>
            <limit>
               <lower>-2.1816</lower>
               <upper>2.1816</upper>
            </limit>
         </axis>
      </joint>
      <joint name="joint5" type="revolute">
         <pose>0.000000 0.000000 0.0 0.000000 0.000000 0.000000</pose>
         <child>link5</child>
         <parent>link4</parent>
         <axis>
            <xyz>0 0 1</xyz>
            <limit>
               <lower>-6.28</lower>
               <upper>6.28</upper>
            </limit>
         </axis>
      </joint>
      <joint name="joint6" type="revolute">
         <pose>0.000000 0.000000 0.0 0.000000 0.000000 0.000000</pose>
         <child>link6</child>
         <parent>link5</parent>
         <axis>
            <xyz>1 0 0</xyz>
            <limit>
               <lower>-6.28</lower>
               <upper>6.28</upper>
            </limit>
         </axis>
      </joint>

 <plugin name="ccc" filename="/home/kevin/research/gazebo/Arm_Control3_7axis/Debug/libArm_Control3_7axis.so" />
   </model>
</sdf>
