<?xml version="1.0" encoding="UTF-8"?>
<sdf version="1.4">
   <model name="ar6aixs">
      <link name="base">
<self_collide>false</self_collide>
         <pose>0.000000 0.000000 0.125 0.000000 0.000000 0</pose>
         <inertial>
            <mass>2000</mass>
            <inertia>
               <ixx>0.1</ixx>
               <ixy>0.0</ixy>
               <iyy>0.1</iyy>
               <ixz>0.0</ixz>
               <iyz>0.0</iyz>
               <izz>0.1</izz>
            </inertia>
         </inertial>
         <collision name="Base">
            <geometry>
               <mesh>
                  <uri>/home/eric/worksapce_tony/Arm_Control3_ar6axis/model/ar6aixs/mesh/base.dae</uri>
               </mesh>
            </geometry>
            <surface>
               <friction>
                  <ode>
                     <mu>100</mu>
                     <mu2>50</mu2>
                  </ode>
               </friction>
            </surface>
         </collision>
         <visual name="Base">
            <geometry>
               <mesh>
                  <uri>/home/eric/worksapce_tony/Arm_Control3_ar6axis/model/ar6aixs/mesh/base.dae</uri>
               </mesh>
            </geometry>
         </visual>
      </link>
      <link name="link1">
<self_collide>false</self_collide>
         <pose>0.000000 0.000000 0.25 0.000000 0.000000 0</pose>
         <inertial>
            <mass>0.1</mass>
            <inertia>
               <ixx>0.1</ixx>
               <ixy>0.0</ixy>
               <iyy>0.1</iyy>
               <ixz>0.0</ixz>
               <iyz>0.0</iyz>
               <izz>0.1</izz>
            </inertia>
         </inertial>
         <collision name="link1">
            <geometry>
               <mesh>
                  <uri>/home/eric/worksapce_tony/Arm_Control3_ar6axis/model/ar6aixs/mesh/link1.dae</uri>
               </mesh>
            </geometry>
            <surface>
               <friction>
                  <ode>
                     <mu>100</mu>
                     <mu2>50</mu2>
                  </ode>
               </friction>
            </surface>
         </collision>
         <visual name="link1">
            <geometry>
               <mesh>
                  <uri>/home/eric/worksapce_tony/Arm_Control3_ar6axis/model/ar6aixs/mesh/link1.dae</uri>
               </mesh>
            </geometry>
         </visual>
      </link>
      <link name="link2">
<self_collide>false</self_collide>
         <pose>0 0.075000  0.345 0.000000 0.000000 0</pose>
         <inertial>
            <mass>0.1</mass>
            <inertia>
               <ixx>0.1</ixx>
               <ixy>0.0</ixy>
               <iyy>0.1</iyy>
               <ixz>0.0</ixz>
               <iyz>0.0</iyz>
               <izz>0.1</izz>
            </inertia>
         </inertial>
         <collision name="link2">
            <geometry>
               <mesh>
                  <uri>/home/eric/worksapce_tony/Arm_Control3_ar6axis/model/ar6aixs/mesh/link2.dae</uri>
               </mesh>
            </geometry>
            <surface>
               <friction>
                  <ode>
                     <mu>100</mu>
                     <mu2>50</mu2>
                  </ode>
               </friction>
            </surface>
         </collision>
         <visual name="link2">
            <geometry>
               <mesh>
                  <uri>/home/eric/worksapce_tony/Arm_Control3_ar6axis/model/ar6aixs/mesh/link2.dae</uri>
               </mesh>
            </geometry>
         </visual>
      </link>
      <link name="link3">
<self_collide>false</self_collide>
         <pose>0 0.075000  0.615 0.000000 0.000000 0</pose>
         <inertial>
            <mass>0.1</mass>
            <inertia>
               <ixx>0.1</ixx>
               <ixy>0.0</ixy>
               <iyy>0.1</iyy>
               <ixz>0.0</ixz>
               <iyz>0.0</iyz>
               <izz>0.1</izz>
            </inertia>
         </inertial>
         <collision name="link3">
            <geometry>
               <mesh>
                  <uri>/home/eric/worksapce_tony/Arm_Control3_ar6axis/model/ar6aixs/mesh/link3.dae</uri>
               </mesh>
            </geometry>
            <surface>
               <friction>
                  <ode>
                     <mu>100</mu>
                     <mu2>50</mu2>
                  </ode>
               </friction>
            </surface>
         </collision>
         <visual name="link3">
            <geometry>
               <mesh>
                  <uri>/home/eric/worksapce_tony/Arm_Control3_ar6axis/model/ar6aixs/mesh/link3.dae</uri>
               </mesh>
            </geometry>
         </visual>
      </link>
      <link name="link4">
<self_collide>false</self_collide>
         <pose>0 0.1810 0.705 0.000000 0.000000 0</pose>
         <inertial>
            <mass>0.1</mass>
            <inertia>
               <ixx>0.1</ixx>
               <ixy>0.0</ixy>
               <iyy>0.1</iyy>
               <ixz>0.0</ixz>
               <iyz>0.0</iyz>
               <izz>0.1</izz>
            </inertia>
         </inertial>
         <collision name="link4">
            <geometry>
               <mesh>
                  <uri>/home/eric/worksapce_tony/Arm_Control3_ar6axis/model/ar6aixs/mesh/link4.dae</uri>
               </mesh>
            </geometry>
            <surface>
               <friction>
                  <ode>
                     <mu>100</mu>
                     <mu2>50</mu2>
                  </ode>
               </friction>
            </surface>
         </collision>
         <visual name="link4">
            <geometry>
               <mesh>
                  <uri>/home/eric/worksapce_tony/Arm_Control3_ar6axis/model/ar6aixs/mesh/link4.dae</uri>
               </mesh>
            </geometry>
         </visual>
      </link>
      <link name="link5">
<self_collide>false</self_collide>
         <pose>0 0.3750  0.705 0.000000 0.000000 0</pose>
         <inertial>
            <mass>0.1</mass>
            <inertia>
               <ixx>0.1</ixx>
               <ixy>0.0</ixy>
               <iyy>0.1</iyy>
               <ixz>0.0</ixz>
               <iyz>0.0</iyz>
               <izz>0.1</izz>
            </inertia>
         </inertial>
         <collision name="link5">
            <geometry>
               <mesh>
                  <uri>/home/eric/worksapce_tony/Arm_Control3_ar6axis/model/ar6aixs/mesh/link5.dae</uri>
               </mesh>
            </geometry>
            <surface>
               <friction>
                  <ode>
                     <mu>100</mu>
                     <mu2>50</mu2>
                  </ode>
               </friction>
            </surface>
         </collision>
         <visual name="link5">
            <geometry>
               <mesh>
                  <uri>/home/eric/worksapce_tony/Arm_Control3_ar6axis/model/ar6aixs/mesh/link5.dae</uri>
               </mesh>
            </geometry>
         </visual>
      </link>
      <link name="link6">
<self_collide>false</self_collide>
         <pose>0  0.3750  0.705 0.000000 0.000000 0</pose>
         <inertial>
            <mass>0.1</mass>
            <inertia>
               <ixx>0.1</ixx>
               <ixy>0.0</ixy>
               <iyy>0.1</iyy>
               <ixz>0.0</ixz>
               <iyz>0.0</iyz>
               <izz>0.1</izz>
            </inertia>
         </inertial>
         <collision name="link6">
            <geometry>
               <mesh>
                  <uri>/home/eric/worksapce_tony/Arm_Control3_ar6axis/model/ar6aixs/mesh/link6.dae</uri>
               </mesh>
            </geometry>
            <surface>
               <friction>
                  <ode>
                     <mu>100</mu>
                     <mu2>50</mu2>
                  </ode>
               </friction>
            </surface>
         </collision>
         <visual name="link6">
            <geometry>
               <mesh>
                  <uri>/home/eric/worksapce_tony/Arm_Control3_ar6axis/model/ar6aixs/mesh/link6.dae</uri>
               </mesh>
            </geometry>
         </visual>
      </link>
      <joint name="joint1" type="revolute">
         <pose>0.000000 0.000000 0.0 0.000000 0.000000 0.000000</pose>
         <child>link1</child>
         <parent>base</parent>
         <axis>
            <xyz>0 0 1</xyz>
            <limit>
               <lower>-2.967</lower>
               <upper>2.967</upper>
            </limit>
         </axis>
      </joint>
      <joint name="joint2" type="revolute">
         <pose>0.000000 0.000000 0.0 0.000000 0.000000 0.000000</pose>
         <child>link2</child>
         <parent>link1</parent>
         <axis>
            <xyz>1 0 0</xyz>
            <limit>
               <lower>-1.4835</lower>
               <upper>2.2689</upper>
            </limit>
         </axis>
      </joint>
      <joint name="joint3" type="revolute">
         <pose>0.000000 0.000000 0.0 0.000000 0.000000 0.000000</pose>
         <child>link3</child>
         <parent>link2</parent>
         <axis>
            <xyz>1 0 0</xyz>
            <limit>
               <lower>-1.919</lower>
               <upper>2.967</upper>
            </limit>
         </axis>
      </joint>
      <joint name="joint4" type="revolute">
         <pose>0.000000 0.000000 0.0 0.000000 0.000000 0.000000</pose>
         <child>link4</child>
         <parent>link3</parent>
         <axis>
            <xyz>0 1 0</xyz>
            <limit>
               <lower>-3.316</lower>
               <upper>3.316</upper>
            </limit>
         </axis>
      </joint>
      <joint name="joint5" type="revolute">
         <pose>0.000000 0.000000 0.0 0.000000 0.000000 0.000000</pose>
         <child>link5</child>
         <parent>link4</parent>
         <axis>
            <xyz>1 0 0</xyz>
            <limit>
               <lower>-2.1816</lower>
               <upper>2.1816</upper>
            </limit>
         </axis>
      </joint>
      <joint name="joint6" type="revolute">
         <pose>0.000000 0.000000 0.0 0.000000 0.000000 0.000000</pose>
         <child>link6</child>
         <parent>link5</parent>
         <axis>
            <xyz>0 1 0 </xyz>
            <limit>
               <lower>-6.28</lower>
               <upper>6.28</upper>
            </limit>
         </axis>
      </joint>
	
	<include>

		
<self_collide>false</self_collide>
		<pose>0 0.546 0.705  1.5708 1.5708 0.000000</pose>
			<uri>/home/eric/worksapce_tony/Arm_Control3_ar6axis/model/gripper</uri>
		</include>

 <!--joint_6_gripper -->
     <joint name="joint7" type="revolute">
      <pose>0.000000 0.000000 0.004386 0.000000 0.000000 0.000000</pose>
      <child>gripper::plam</child>
      <parent>link6</parent>
      <axis>
         <xyz>0 0 1</xyz>
         <limit>
          <lower>0</lower>
          <upper>0</upper>
         </limit>
      </axis>
   </joint>

 <plugin name="ccc" filename="/home/eric/worksapce_tony/Arm_Control3_ar6axis/Debug/libArm_Control3_ar6axis.so" />
   </model>
</sdf>
