<?xml version="1.0"?>
<sdf version="1.4">
    <model name="gripper">
		

       <link name="plam">
            <pose>0 0 2.125 0 0 0 </pose>
            <inertial>
                                       <mass>12</mass>
        <inertia>
          <ixx>0.5</ixx>
          <ixy>0.0</ixy><iyy>0.5</iyy>
          <ixz>0.0</ixz><iyz>0.0</iyz><izz>1.0</izz>
</inertia>
            </inertial>
            <collision name="collision">
			

 			<surface>
          <friction>
            <ode>
              <mu>100000.0</mu>
              <mu2>100000.0</mu2>
              <slip1>0.0</slip1>
              <slip2>0.0</slip2>
            </ode>
          </friction>
        </surface>
                <geometry>
                    <box>
                        <size>1.5 3 0.25</size>
                    </box>
                </geometry>
            </collision>
            <visual name="visual">
                <geometry>
                    <box>
                        <size>1.5 3 0.25</size>
                    </box>
                </geometry>
            </visual>
        </link>
















        <link name="right_finger">
            <pose>0 1.375 1 0  0 0 </pose>
            <inertial>
                                                 <mass>12</mass>
        <inertia>
          <ixx>0.5</ixx>
          <ixy>0.0</ixy><iyy>0.5</iyy>
          <ixz>0.0</ixz><iyz>0.0</iyz><izz>1.0</izz>
</inertia>
            </inertial>
            <collision name="collision">
			

 <surface>
          <friction>
            <ode>
              <mu>100000.0</mu>
              <mu2>100000.0</mu2>
              <slip1>0.0</slip1>
              <slip2>0.0</slip2>
            </ode>
          </friction>
        </surface>
                <geometry>
														
                    <box>
                        <size>1 0.25 2</size>
                    </box>
                </geometry>
            </collision>
            <visual name="visual">
                <geometry>
							
                    <box>
                        <size>1 0.25 2</size>
                    </box>
                </geometry>
            </visual>
        </link>


        <link name="left_finger">
            <pose>0 -1.375 1 0  0 0 </pose>
            <inertial>
                                                     <mass>12</mass>
        <inertia>
          <ixx>0.5</ixx>
          <ixy>0.0</ixy><iyy>0.5</iyy>
          <ixz>0.0</ixz><iyz>0.0</iyz><izz>1.0</izz>
				</inertia>
            </inertial>
            <collision name="collision">

 <surface>
          <friction>
            <ode>
              <mu>100000.0</mu>
              <mu2>100000.0</mu2>
              <slip1>0.0</slip1>
              <slip2>0.0</slip2>
            </ode>
          </friction>
        </surface>
                <geometry>
									
                    <box>
                        <size>1 0.25 2</size>
                    </box>
                </geometry>
            </collision>
            <visual name="visual">
                <geometry>
								
                    <box>
                        <size>1 0.25 2</size>
                    </box>
                </geometry>
            </visual>
        </link>


				<joint name="right_joint" type="prismatic">
            <pose>0  0 1 0 0 0</pose>
            <child>right_finger</child>
            <parent>plam</parent>
            <axis>
                <xyz>0 1 0</xyz>
															<limit><lower>-0.751</lower><upper>0</upper></limit>
            </axis>
        </joint>



        <joint name="left_joint" type="prismatic">
            <pose>0 0 1 0 0 0</pose>
            <child>left_finger</child>
            <parent>plam</parent>
            <axis>
							<xyz>0 1 0 </xyz>

<limit><lower>0</lower><upper>0.751</upper></limit>
						</axis>
        </joint>


		<plugin name="df" filename="/home/gotony5614/Dropbox/gazebo/XLAB/gripppertest/dist/Debug/GNU-Linux-x86/libgripppertest.so"/>



    </model>
</sdf>
