<?xml version="1.0" encoding="UTF-8"?>
<sdf version="1.4">
   <model name="gripper">
      <link name="plam">
         <pose>0 0 2.125 0 0 0</pose>
         <inertial>
            <mass>.1</mass>
            <inertia>
               <ixx>0.05</ixx>
               <ixy>0.0</ixy>
               <iyy>0.05</iyy>
               <ixz>0.0</ixz>
               <iyz>0.0</iyz>
               <izz>0.05</izz>
            </inertia>
         </inertial>
         <collision name="collision">
            <surface>
               <friction>
                  <ode>
                     <mu>100000.0</mu>
                     <mu2>100000.0</mu2>
                     <slip1>0.0</slip1>
                     <slip2>0.0</slip2>
                  </ode>
               </friction>
            </surface>
            <geometry>
               <box>
                  <size>1.5 3 0.25</size>
               </box>
            </geometry>
         </collision>
         <visual name="visual">
            <geometry>
               <box>
                  <size>1.5 3 0.25</size>
               </box>
            </geometry>
            <material>
               <script>
                  <uri>file://media/materials/scripts/gazebo.material</uri>
                  <name>Gazebo/Red</name>
               </script>
            </material>
         </visual>
      </link>
      <link name="right_finger">
         <pose>0 .85 1 0  0 0</pose>
         <inertial>
            <mass>.1</mass>
            <inertia>
               <ixx>0.05</ixx>
               <ixy>0.0</ixy>
               <iyy>0.05</iyy>
               <ixz>0.0</ixz>
               <iyz>0.0</iyz>
               <izz>0.05</izz>
            </inertia>
         </inertial>
         <collision name="collision">
            <surface>
               <bounce>
									<restitution_coefficient>0</restitution_coefficient>
                  <threshold>99999999</threshold>
               </bounce>
               <friction>
                  <ode>
                     <mu>100000.0</mu>
                     <mu2>100000.0</mu2>
                     <slip1>0.0</slip1>
                     <slip2>0.0</slip2>
                  </ode>
               </friction>
            </surface>
            <geometry>
               <mesh><scale>1.2 1 1</scale>
                  <uri>/home/gotony5614/Dropbox/gazebo/MODELs/model/gripper/right_finger.dae</uri>
               </mesh>
            </geometry>
         </collision>
         <visual name="visual">
            <material>
               <script>
                  <uri>file://media/materials/scripts/gazebo.material</uri>
                  <name>Gazebo/Red</name>
               </script>
            </material>
            <geometry>
               <mesh><scale>1.2 1 1</scale>
                  <uri>/home/gotony5614/Dropbox/gazebo/MODELs/model/gripper/right_finger.dae</uri>
               </mesh>
            </geometry>
         </visual>
      </link>






<!--
<link name="right_nail">
         <pose>0 1.25 .125 0  0 0</pose>
         <inertial>
            <mass>.1</mass>
            <inertia>
               <ixx>0.05</ixx>
               <ixy>0.0</ixy>
               <iyy>0.05</iyy>
               <ixz>0.0</ixz>
               <iyz>0.0</iyz>
               <izz>0.05</izz>
            </inertia>
         </inertial>
         <collision name="collision">
            <surface>
               <bounce>
									<restitution_coefficient>0</restitution_coefficient>
                  <threshold>99999999</threshold>
               </bounce>
               <friction>
                  <ode>
                     <mu>100000.0</mu>
                     <mu2>100000.0</mu2>
                     <slip1>0.0</slip1>
                     <slip2>0.0</slip2>
                  </ode>
               </friction>
            </surface>
            <geometry>
               <box>
                  <size>1.25 0.025 0.025</size>
               </box>
            </geometry>
         </collision>
         <visual name="visual">
            <material>
               <script>
                  <uri>file://media/materials/scripts/gazebo.material</uri>
                  <name>Gazebo/Red</name>
               </script>
            </material>
            <geometry>
               <box>
                  <size>1.25 0.025 0.025</size>
               </box>
            </geometry>
         </visual>
      </link>






   


    <joint name="right_nail" type="revolute">
      <pose>0 -0.00625 0 0 0 0</pose>
      <child>right_nail</child>
      <parent>right_finger</parent>
      <axis>
        <limit>
          <lower>0</lower>
          <upper>0</upper>
        </limit>
        <xyz>0 0 1</xyz>
      </axis>
    </joint>




-->



      <link name="left_finger">
         <pose>0 -.725 1 0  0 0</pose>
         <inertial>
            <mass>.1</mass>
            <inertia>
               <ixx>0.05</ixx>
               <ixy>0.0</ixy>
               <iyy>0.05</iyy>
               <ixz>0.0</ixz>
               <iyz>0.0</iyz>
               <izz>0.05</izz>
            </inertia>
         </inertial>
         <collision name="collision">
            <surface>
               <bounce>
									<restitution_coefficient>0</restitution_coefficient>
                  <threshold>99999999</threshold>
               </bounce>
               <friction>
                  <ode>
                     <mu>100000.0</mu>
                     <mu2>100000.0</mu2>
                     <slip1>0.0</slip1>
                     <slip2>0.0</slip2>
                  </ode>
               </friction>
            </surface>
            <geometry>
               <mesh>
<scale>1.2 1 1</scale>
                  <uri>/home/gotony5614/Dropbox/gazebo/MODELs/model/gripper/left_finger.dae</uri>
               </mesh>
            </geometry>
         </collision>
         <visual name="visual">
            <material>
               <script>
                  <uri>file://media/materials/scripts/gazebo.material</uri>
                  <name>Gazebo/Blue</name>
               </script>
            </material>
            <geometry>
               <mesh><scale>1.2 1 1</scale>
                  <uri>/home/gotony5614/Dropbox/gazebo/MODELs/model/gripper/left_finger.dae</uri>
               </mesh>
            </geometry>
         </visual>
      </link>
    <!--  <link name="left_nail">
         <pose>0 -1.25 .125 0  0 0</pose>
         <inertial>
            <mass>.1</mass>
            <inertia>
               <ixx>0.05</ixx>
               <ixy>0.0</ixy>
               <iyy>0.05</iyy>
               <ixz>0.0</ixz>
               <iyz>0.0</iyz>
               <izz>0.05</izz>
            </inertia>
         </inertial>
         <collision name="collision">
            <surface>
               <bounce>
                  <threshold>99999999</threshold>
               </bounce>
               <friction>
                  <ode>
                     <mu>100000.0</mu>
                     <mu2>100000.0</mu2>
                     <slip1>0.0</slip1>
                     <slip2>0.0</slip2>
                  </ode>
               </friction>
            </surface>
            <geometry>
               <box>
                  <size>1.25 0.025 0.025</size>
               </box>
            </geometry>
         </collision>
         <visual name="visual">
            <material>
               <script>
                  <uri>file://media/materials/scripts/gazebo.material</uri>
                  <name>Gazebo/Red</name>
               </script>
            </material>
            <geometry>
               <box>
                  <size>1.25 0.025 0.025</size>
               </box>
            </geometry>
         </visual>
      </link>






   


    <joint name="left_nail" type="revolute">
      <pose>0 0.00625 0 0 0 0</pose>
      <child>left_nail</child>
      <parent>left_finger</parent>
      <axis>
        <limit>
          <lower>0</lower>
          <upper>0</upper>
        </limit>
        <xyz>0 0 1</xyz>
      </axis>
    </joint>










-->





      <joint name="right_joint" type="prismatic">
         <pose>0  0 1 0 0 0</pose>
         <child>right_finger</child>
         <parent>plam</parent>
         <axis>
            <dynamics>
               <damping>5</damping>
               <friction>5</friction>
            </dynamics>
            <xyz>0 1 0</xyz>
            <dynamics>
               <damping>5</damping>
               <friction>5</friction>
            </dynamics>
            <limit>
               <lower>-0.65</lower>
               <upper>0</upper>
            </limit>
         </axis>
      </joint>
      <joint name="left_joint" type="prismatic">
         <pose>0 0 1 0 0 0</pose>
         <child>left_finger</child>
         <parent>plam</parent>
         <axis>
            <dynamics>
               <damping>5</damping>
               <friction>5</friction>
            </dynamics>
            <xyz>0 1 0</xyz>
            <limit>
               <lower>0</lower>
               <upper>0.65</upper>
            </limit>
         </axis>
      </joint>
      <!--<plugin name="df" filename="/home/gotony5614/Dropbox/gazebo/ITRI/grippertest/dist/Debug/GNU-Linux-x86/libgrippertest.so"/>
	
	-->
   </model>
</sdf>
