<?xml version="1.0" ?>
<sdf version="1.4">


<model name="6axistest">

  <link name="base">
			
			<pose>0 0 5 0 0 0</pose>
			<inertial>
          <!--<inertia>
            <ixx>1</ixx> <ixy>0</ixy> <ixz>0</ixz>
            <iyy>1</iyy> <iyz>0</iyz>
            <izz>1</izz>
          <inertia>-->
				<mass> 200</mass>
			</inertial> 
			<collision name="Base_collision">
        <geometry>
					<cylinder>
						<radius>3</radius>
						<length>10</length>
					</cylinder>
        </geometry>
        <surface>
          <friction>
            <ode>
              <mu>100</mu>
              <mu2>50</mu2>
            </ode>
          </friction>
        </surface>
      </collision>
      <visual name="Base_visual">
        <geometry>
<cylinder>
						<radius>3</radius>
						<length>10</length>
					</cylinder>

        </geometry>
      </visual>
    </link>


<!--joint_base_1-->
		<joint name="joint1" type="revolute">
			<pose>0 0.0 -0.5 0 0 0</pose>
      <child>link1_1</child>
      <parent>base</parent>
      <axis><dynamics><friction>500</friction></dynamics>
      	<xyz> 0 0 1</xyz>
     	</axis>
    </joint>


    <link name="link1_1">
			
			<pose>0 0 10.5 0 0 0</pose>
			<inertial>
          <!--<inertia>
            <ixx>1</ixx> <ixy>0</ixy> <ixz>0</ixz>
            <iyy>1</iyy> <iyz>0</iyz>
            <izz>1</izz>
          <inertia>-->
				<mass>0.1</mass>
			</inertial> 
			<collision name="Base_collision">
        <geometry>
					<cylinder>
						<radius>3</radius>
						<length>1</length>
					</cylinder>
        </geometry>
        <surface>
          <friction>
            <ode>
              <mu>0</mu>
              <mu2>0</mu2>
            </ode>
          </friction>
        </surface>
      </collision>
      <visual name="Base_visual">
        <geometry>
					<cylinder>
						<radius>3</radius>
						<length>1</length>
					</cylinder>
        </geometry>
      </visual>
    </link>


		<joint name="link1_2_to_link1_1" type="revolute">
			<pose>0 0.0 -3 0 0 0</pose>
      <child>link1_2</child>
      <parent>link1_1</parent>
      <axis>
				<limit><lower>0</lower><upper>0</upper></limit>
      	<xyz> 0 0 1</xyz>
     	</axis>
    </joint>

    <link name="link1_2">
			
			<pose>0 -2 14 0 0 0</pose>
			<inertial>
          <!--<inertia>
            <ixx>1</ixx> <ixy>0</ixy> <ixz>0</ixz>
            <iyy>1</iyy> <iyz>0</iyz>
            <izz>1</izz>
          <inertia>-->
				<mass>0.1</mass>
			</inertial> 
			<collision name="Base_collision">
        <geometry>
					<box>
						<size>5 1 6</size>
					</box>
        </geometry>
        <surface>
          <friction>
            <ode>
              <mu>0</mu>
              <mu2>0</mu2>
            </ode>
          </friction>
        </surface>
      </collision>
      <visual name="Base_visual">
        <geometry>
			
	<box>
						<size>5 1 6</size>
					</box>
        </geometry>
      </visual>
    </link>







<!--joint_1_2-->

		<joint name="joint2" type="revolute">
			<pose>0 0.0 1.5 0 0 0</pose>
      <child>link2_1</child>
      <parent>link1_2</parent>
      <axis><dynamics><friction>50000</friction></dynamics>
      	<xyz> 0 1 0 </xyz>
     	</axis>
    </joint>
    <link name="link2_1">
			
			<pose>0 0 17 1.5708 0 0</pose>
			<inertial>
          <!--<inertia>
            <ixx>1</ixx> <ixy>0</ixy> <ixz>0</ixz>
            <iyy>1</iyy> <iyz>0</iyz>
            <izz>1</izz>
          <inertia>-->
				<mass>0.1</mass>
			</inertial> 
			<collision name="Base_collision">
        <geometry>
					<cylinder>
						<radius>2</radius>
						<length>3</length>
					</cylinder>
        </geometry>
        <surface>
          <friction>
            <ode>
              <mu>0</mu>
              <mu2>0</mu2>
            </ode>
          </friction>
        </surface>
      </collision>
      <visual name="Base_visual">
        <geometry>
					<cylinder>
						<radius>2</radius>
						<length>3</length>
					</cylinder>
        </geometry>
      </visual>
    </link>



		<joint name="link2_1_to_link2_2" type="revolute">
			<pose>0 0.0 -1.5 0 0 0</pose>
      <child>link2_1</child>
      <parent>link2_2</parent>
      <axis>
				<limit><lower>0</lower><upper>0</upper></limit>
      	<xyz> 0 0 1</xyz>
     	</axis>
    </joint>



    <link name="link2_2">
			
			<pose>0 2 30 0 0 0</pose>
			<inertial>
          <!--<inertia>
            <ixx>1</ixx> <ixy>0</ixy> <ixz>0</ixz>
            <iyy>1</iyy> <iyz>0</iyz>
            <izz>1</izz>
          <inertia>-->
				<mass>0.1</mass>
			</inertial> 
			<collision name="Base_collision">
        <geometry>
					<box>
						<size>5 1 28</size>
					</box>
        </geometry>
        <surface>
          <friction>
            <ode>
              <mu>0</mu>
              <mu2>0</mu2>
            </ode>
          </friction>
        </surface>
      </collision>
      <visual name="Base_visual">
        <geometry>
					<box>
						<size>5 1 28</size>
					</box>
        </geometry>
      </visual>
    </link>

<!--joint_2_3-->

		<joint name="joint3" type="revolute">
			<pose>0 0.0 -1.5 0 0 0</pose>
      <child>link3_1</child>
      <parent>link2_2</parent>
      <axis><dynamics><friction>50000</friction></dynamics>
      	<xyz> 0 1 0 </xyz>
     	</axis>
    </joint>






    <link name="link3_1">
			
			<pose>0 0 41 1.5708 0 0</pose>
			<inertial>
          <!--<inertia>
            <ixx>1</ixx> <ixy>0</ixy> <ixz>0</ixz>
            <iyy>1</iyy> <iyz>0</iyz>
            <izz>1</izz>
          <inertia>-->
				<mass>0.1</mass>
			</inertial> 
			<collision name="Base_collision">
        <geometry>
					<cylinder>
						<radius>2</radius>
						<length>3</length>
					</cylinder>
        </geometry>
        <surface>
          <friction>
            <ode>
              <mu>0</mu>
              <mu2>0</mu2>
            </ode>
          </friction>
        </surface>
      </collision>
      <visual name="Base_visual">
        <geometry>
					<cylinder>
						<radius>2</radius>
						<length>3</length>
					</cylinder>
        </geometry>
      </visual>
    </link>


		<joint name="link3_1_to_link3_2" type="revolute">
			<pose>0 0.0 1.5 0 0 0</pose>
      <child>link3_1</child>
      <parent>link3_2</parent>
      <axis>
				<limit><lower>0</lower><upper>0</upper></limit>
      	<xyz> 0 0 1</xyz>
     	</axis>
    </joint>


    <link name="link3_2">
			
			<pose>0 -2 41 0 0 0</pose>
			<inertial>
          <!--<inertia>
            <ixx>1</ixx> <ixy>0</ixy> <ixz>0</ixz>
            <iyy>1</iyy> <iyz>0</iyz>
            <izz>1</izz>
          <inertia>-->
				<mass>0.1</mass>
			</inertial> 
			<collision name="Base_collision">
        <geometry>
					<box>
						<size>5 1 8</size>
					</box>
        </geometry>
        <surface>
          <friction>
            <ode>
              <mu>0</mu>
              <mu2>0</mu2>
            </ode>
          </friction>
        </surface>
      </collision>
      <visual name="Base_visual">
        <geometry>
					<box>
						<size>5 1 8</size>
					</box>
        </geometry>
      </visual>
    </link>


		<joint name="link3_3_to_link3_2" type="revolute">
			<pose>0 -1.5 0 0 0 0</pose>
      <child>link3_3</child>
      <parent>link3_2</parent>
      <axis>
				<limit><lower>0</lower><upper>0</upper></limit>
      	<xyz> 0 0 1</xyz>
     	</axis>
    </joint>



    <link name="link3_3">
			
			<pose>0 0 44.5 0 0 0</pose>
			<inertial>
          <!--<inertia>
            <ixx>1</ixx> <ixy>0</ixy> <ixz>0</ixz>
            <iyy>1</iyy> <iyz>0</iyz>
            <izz>1</izz>
          <inertia>-->
				<mass>0.1</mass>
			</inertial> 
			<collision name="Base_collision">
        <geometry>
					<box>
						<size>3 3 1</size>
					</box>
        </geometry>
        <surface>
          <friction>
            <ode>
              <mu>0</mu>
              <mu2>0</mu2>
            </ode>
          </friction>
        </surface>
      </collision>
      <visual name="Base_visual">
        <geometry>
					<box>
						<size>3 3 1</size>
					</box>
        </geometry>
      </visual>
    </link>






<!--joint_4_3-->

		<joint name="joint4" type="revolute">
			<pose>0 0.0 -10.5 0 0 0</pose>
      <child>link4_1</child>
      <parent>link3_3</parent>
      <axis>
				
      	<xyz> 0  0 1</xyz>
     	</axis>
    </joint>









    <link name="link4_1">
			
			<pose>0 0 55.5 0 0 0</pose>
			<inertial>
				<mass>0.1</mass>
			</inertial> 
			<collision name="Base_collision">
        <geometry>
					<cylinder>
						<radius>2</radius>
						<length>21</length>
					</cylinder>
        </geometry>
        <surface>
          <friction>
            <ode>
              <mu>0</mu>
              <mu2>0</mu2>
            </ode>
          </friction>
        </surface>
      </collision>
      <visual name="Base_visual">
        <geometry>
					<cylinder>
						<radius>2</radius>
						<length>21</length>
					</cylinder>
        </geometry>
      </visual>
    </link>

		<joint name="link4_1_to_link4_2" type="revolute">
			<pose>0 0.0 -2 0 0 0</pose>
      <child>link4_2</child>
      <parent>link4_1</parent>
      <axis>
				<limit><lower>0</lower><upper>0</upper></limit>
      	<xyz> 0 0 1</xyz>
     	</axis>
    </joint>







    <link name="link4_2">
			
			<pose>0 1 68 0 0 0</pose>
			<inertial>
          <!--<inertia>
            <ixx>1</ixx> <ixy>0</ixy> <ixz>0</ixz>
            <iyy>1</iyy> <iyz>0</iyz>
            <izz>1</izz>
          <inertia>-->
				<mass>0.1</mass>
			</inertial> 
			<collision name="Base_collision">
        <geometry>
					<box>
						<size>3 1 4</size>
					</box>
        </geometry>
        <surface>
          <friction>
            <ode>
              <mu>0</mu>
              <mu2>0</mu2>
            </ode>
          </friction>
        </surface>
      </collision>
      <visual name="Base_visual">
        <geometry>
					<box>
						<size>3 1 4</size>
					</box>
        </geometry>
      </visual>
    </link>







<!--joint_4_5-->

		<joint name="joint5" type="revolute">
			<pose>0 0.0 -0.5 0 0 0</pose>
      <child>link5_1</child>
      <parent>link4_2</parent>
      <axis><dynamics><friction>50000</friction></dynamics>
      	<xyz> 0 1 0 </xyz>
     	</axis>
    </joint>



    <link name="link5_1">
			
			<pose>0 0 68.5 1.5708 0 0</pose>
			<inertial>
          <!--<inertia>
            <ixx>1</ixx> <ixy>0</ixy> <ixz>0</ixz>
            <iyy>1</iyy> <iyz>0</iyz>
            <izz>1</izz>
          <inertia>-->
				<mass>0.1</mass>
			</inertial> 
			<collision name="Base_collision">
        <geometry>
					<cylinder>
						<radius>2</radius>
						<length>1</length>
					</cylinder>
        </geometry>
        <surface>
          <friction>
            <ode>
              <mu>0</mu>
              <mu2>0</mu2>
            </ode>
          </friction>
        </surface>
      </collision>
      <visual name="Base_visual">
        <geometry>
					<cylinder>
						<radius>2</radius>
						<length>1</length>
					</cylinder>
        </geometry>
      </visual>
    </link>



		<joint name="link5_2_to_link5_1" type="revolute">
			<pose>0 0.0 0.5 0 0 0</pose>
      <child>link5_1</child>
      <parent>link5_2</parent>
      <axis>
				<limit><lower>0</lower><upper>0</upper></limit>
      	<xyz> 0 0 1</xyz>
     	</axis>
    </joint>




    <link name="link5_2">
			
			<pose>0 -1 69.5 0 0 0</pose>
			<inertial>
          <!--<inertia>
            <ixx>1</ixx> <ixy>0</ixy> <ixz>0</ixz>
            <iyy>1</iyy> <iyz>0</iyz>
            <izz>1</izz>
          <inertia>-->
				<mass>0.1</mass>
			</inertial> 
			<collision name="Base_collision">
        <geometry>
					<box>
						<size>3 1 3</size>
					</box>
        </geometry>
        <surface>
          <friction>
            <ode>
              <mu>0</mu>
              <mu2>0</mu2>
            </ode>
          </friction>
        </surface>
      </collision>
      <visual name="Base_visual">
        <geometry>
					<box>
						<size>3 1 3</size>
					</box>
        </geometry>
      </visual>
    </link>



		<joint name="link5_2_to_link5_3" type="revolute">
			<pose>0 0.0 1.5 0 0 0</pose>
      <child>link5_2</child>
      <parent>link5_3</parent>
      <axis>
				<limit><lower>0</lower><upper>0</upper></limit>
      	<xyz> 0 0 1</xyz>
     	</axis>
    </joint>





    <link name="link5_3">
			
			<pose>0 0 71.5 0 0 0</pose>
			<inertial>
          <!--<inertia>
            <ixx>1</ixx> <ixy>0</ixy> <ixz>0</ixz>
            <iyy>1</iyy> <iyz>0</iyz>
            <izz>1</izz>
          <inertia>-->
				<mass>0.1</mass>
			</inertial> 
			<collision name="Base_collision">
        <geometry>
					<cylinder>
						<radius>1.5</radius>
						<length>1</length>
					</cylinder>
        </geometry>
        <surface>
          <friction>
            <ode>
              <mu>0</mu>
              <mu2>0</mu2>
            </ode>
          </friction>
        </surface>
      </collision>
      <visual name="Base_visual">
        <geometry>
					<cylinder>
						<radius>1.5</radius>
						<length>1</length>
					</cylinder>
        </geometry>
      </visual>
    </link>





<!--joint_6_5-->

		<joint name="joint6" type="revolute">
			<pose>0 0.0 -3.25 0 0 0</pose>
      <child>link6</child>
      <parent>link5_3</parent>
      <axis><dynamics><friction>50000</friction></dynamics>
      	<xyz> 0 0 1</xyz>
     	</axis>
    </joint>





    <link name="link6">
			
			<pose>0 0 75.25 0 0 0</pose>
			<inertial>
          <!--<inertia>
            <ixx>1</ixx> <ixy>0</ixy> <ixz>0</ixz>
            <iyy>1</iyy> <iyz>0</iyz>
            <izz>1</izz>
          <inertia>-->
				<mass>0.1</mass>
			</inertial> 
			<collision name="Base_collision">
        <geometry>
					<cylinder>
						<radius>.5</radius>
						<length>6.5</length>
					</cylinder>
        </geometry>
        <surface>
          <friction>
            <ode>
              <mu>0</mu>
              <mu2>0</mu2>
            </ode>
          </friction>
        </surface>
      </collision>
      <visual name="Base_visual">
        <geometry>
					<cylinder>
						<radius>.5</radius>
						<length>6.5</length>
					</cylinder>
        </geometry>
      </visual>
    </link>


<!--joint_6_7-->

		<joint name="joint7" type="revolute">
			<pose>0 0 -0.01 0 0 0</pose>
      <child>link7</child>
      <parent>link6</parent>
      <axis>
				<limit><lower>0</lower><upper>0</upper></limit>
      	<xyz> 0 0 1</xyz>
     	</axis>
    </joint>




<!--標記手臂端點的座標 -->
    <link name="link7">
			
			<pose>0 0 78.50 0 0 0</pose>
			<inertial>
          <!--<inertia>
            <ixx>1</ixx> <ixy>0</ixy> <ixz>0</ixz>
            <iyy>1</iyy> <iyz>0</iyz>
            <izz>1</izz>
          <inertia>-->
				<mass>0.1</mass>
			</inertial> 
			<collision name="Base_collision">
        <geometry>
					<cylinder>
						<radius>0.02</radius>
						<length>0.02</length>
					</cylinder>
        </geometry>
        <surface>
          <friction>
            <ode>
              <mu>0</mu>
              <mu2>0</mu2>
            </ode>
          </friction>
        </surface>
      </collision>
      <visual name="Base_visual">
        <geometry>
					<cylinder>
						<radius>0.02</radius>
						<length>0.02</length>
					</cylinder>
        </geometry>
      </visual>
    </link>



<!--joint_7_dummylink-->

		<joint name="staticjoint" type="revolute">
			<pose>0 0 0.01 0 0 0</pose>
      <child>link7</child>
      <parent>dummylink</parent>
      <axis>
				<xyz> 0 0 1</xyz>
     	</axis>
    </joint>

    <link name="dummylink">
			
			<pose>0 0 78.52 0 0 0</pose>
			<inertial>
				<mass>0.1</mass>
			</inertial> 
			<collision name="collision">
        <geometry>
					<cylinder>
						<radius>.2</radius>
						<length>.2</length>
					</cylinder>
        </geometry>
        <surface>
          <friction>
            <ode>
              <mu>0</mu>
              <mu2>0</mu2>
            </ode>
          </friction>
        </surface>
      </collision>
      <visual name="visual">
        <geometry>
					<cylinder>
						<radius>.2</radius>
						<length>.2</length>
					</cylinder>
        </geometry>
      </visual>
    </link>





<!--


-->

<plugin name="ccc" filename="/home/gotony5614/Dropbox/gazebo/XLAB/Arm_Control/dist/Debug/GNU-Linux-x86/libArm_Control.so"/>




</model>    
</sdf>
